<?xml version="1.0" ?>
<sdf version="1.8">
    <world name="split_world">
        <physics name="1ms" type="ode">
            <max_step_size>0.001</max_step_size>
            <real_time_factor>1.0</real_time_factor>
        </physics>
        <plugin filename="gz-sim-physics-system" name="gz::sim::systems::Physics" />
        <plugin filename="gz-sim-user-commands-system" name="gz::sim::systems::UserCommands" />
        <plugin filename="gz-sim-scene-broadcaster-system" name="gz::sim::systems::SceneBroadcaster" />
        <plugin filename="gz-sim-sensors-system" name="gz::sim::systems::Sensors"><render_engine>ogre2</render_engine></plugin>

        <light type="directional" name="sun"><pose>0 0 10 0 0 0</pose><direction>-0.5 0.1 -0.9</direction></light>

        <model name="split_floor"><static>true</static><pose>10 0 0 0 0 0</pose>
            <link name="tile"><pose>0 5 0 0 0 0</pose>
                <collision name="c"><geometry><box><size>20 10 0.1</size></box></geometry><surface><friction><ode><mu>0.0</mu><mu2>0.0</mu2></ode></friction></surface></collision>
                <visual name="v"><geometry><box><size>20 10 0.1</size></box></geometry><material><ambient>1 1 1 1</ambient><diffuse>1 1 1 1</diffuse></material></visual></link>
            <link name="carpet"><pose>0 -5 0 0 0 0</pose>
                <collision name="c"><geometry><box><size>20 10 0.1</size></box></geometry><surface><friction><ode><mu>100.0</mu><mu2>100.0</mu2></ode></friction></surface></collision>
                <visual name="v"><geometry><box><size>20 10 0.1</size></box></geometry><material><ambient>0.1 0.1 0.1 1</ambient><diffuse>0.1 0.1 0.1 1</diffuse></material></visual></link>
        </model>

        <model name="bot_v2">
            <pose>1 0 0.2 0 0 0</pose>
            <link name="base_link">
                <inertial><mass>2.0</mass><inertia><ixx>0.01</ixx><iyy>0.01</iyy><izz>0.01</izz></inertia></inertial>
                <visual name="v"><geometry><box><size>0.4 0.3 0.1</size></box></geometry></visual>
                <collision name="c"><geometry><box><size>0.4 0.3 0.1</size></box></geometry></collision>
            </link>
            <link name="left_wheel">
                <pose>0.1 0.18 -0.05 -1.5708 0 0</pose>
                <visual name="v"><geometry><cylinder><radius>0.1</radius><length>0.05</length></cylinder></geometry></visual>
                <collision name="c"><geometry><cylinder><radius>0.1</radius><length>0.05</length></cylinder></geometry></collision>
            </link>
            <link name="right_wheel">
                <pose>0.1 -0.18 -0.05 -1.5708 0 0</pose>
                <visual name="v"><geometry><cylinder><radius>0.1</radius><length>0.05</length></cylinder></geometry></visual>
                <collision name="c"><geometry><cylinder><radius>0.1</radius><length>0.05</length></cylinder></geometry></collision>
            </link>
            <joint name="left_wheel_joint" type="revolute"><parent>base_link</parent><child>left_wheel</child><axis><xyz>0 0 1</xyz><limit><lower>-1e16</lower><upper>1e16</upper></limit></axis></joint>
            <joint name="right_wheel_joint" type="revolute"><parent>base_link</parent><child>right_wheel</child><axis><xyz>0 0 1</xyz><limit><lower>-1e16</lower><upper>1e16</upper></limit></axis></joint>
            
            <link name="camera_link"><pose>0.2 0 0.1 0 0.5 0</pose>
                <visual name="v"><geometry><box><size>0.05 0.05 0.05</size></box></geometry></visual>
                <sensor name="camera" type="camera">
                    <always_on>1</always_on><update_rate>20</update_rate><visualize>true</visualize>
                    <topic>/camera/image_raw</topic>
                </sensor>
            </link>
            <joint name="camera_joint" type="fixed"><parent>base_link</parent><child>camera_link</joint>

            <plugin filename="gz-sim-diff-drive-system" name="gz::sim::systems::DiffDrive">
                <left_joint>left_wheel_joint</left_joint>
                <right_joint>right_wheel_joint</right_joint>
                <wheel_separation>0.36</wheel_separation>
                <wheel_radius>0.1</wheel_radius>
                <topic>/cmd_vel</topic>
                <odom_topic>/model/bot_v2/odometry</odom_topic>
            </plugin>
        </model>
    </world>
</sdf>