<?xml version="1.0" ?>
<robot name="bot_v2">
  <link name="base_link">
    <inertial>
      <mass value="2.0"/>
      <inertia ixx="0.01" ixy="0" ixz="0" iyy="0.01" iyz="0" izz="0.01"/>
    </inertial>
    <visual><geometry><box size="0.4 0.3 0.1"/></geometry></visual>
    <collision><geometry><box size="0.4 0.3 0.1"/></geometry></collision>
  </link>

  <link name="left_wheel">
    <inertial><mass value="0.5"/><inertia ixx="0.001" ixy="0" ixz="0" iyy="0.001" iyz="0" izz="0.001"/></inertial>
    <visual><geometry><cylinder radius="0.1" length="0.05"/></geometry></visual>
    <collision><geometry><cylinder radius="0.1" length="0.05"/></geometry></collision>
  </link>
  <joint name="left_wheel_joint" type="continuous">
    <parent link="base_link"/><child link="left_wheel"/>
    <origin xyz="0.1 0.18 -0.05" rpy="-1.5708 0 0"/><axis xyz="0 0 1"/>
  </joint>

  <link name="right_wheel">
    <inertial><mass value="0.5"/><inertia ixx="0.001" ixy="0" ixz="0" iyy="0.001" iyz="0" izz="0.001"/></inertial>
    <visual><geometry><cylinder radius="0.1" length="0.05"/></geometry></visual>
    <collision><geometry><cylinder radius="0.1" length="0.05"/></geometry></collision>
  </link>
  <joint name="right_wheel_joint" type="continuous">
    <parent link="base_link"/><child link="right_wheel"/>
    <origin xyz="0.1 -0.18 -0.05" rpy="-1.5708 0 0"/><axis xyz="0 0 1"/>
  </joint>

  <link name="caster">
    <inertial><mass value="0.1"/><inertia ixx="0.0001" ixy="0" ixz="0" iyy="0.0001" iyz="0" izz="0.0001"/></inertial>
    <collision><geometry><sphere radius="0.05"/></geometry></collision>
  </link>
  <joint name="caster_joint" type="fixed">
    <parent link="base_link"/><child link="caster"/>
    <origin xyz="-0.15 0 -0.1" rpy="0 0 0"/>
  </joint>

  <link name="camera_link"><visual><geometry><box size="0.05 0.05 0.05"/></geometry></visual></link>
  <joint name="camera_joint" type="fixed"><parent link="base_link"/><child link="camera_link"/><origin xyz="0.2 0 0.08" rpy="0 0.8 0"/></joint>

  <gazebo reference="camera_link">
    <sensor name="camera" type="camera">
      <camera><horizontal_fov>1.047</horizontal_fov><image><width>320</width><height>240</height></image></camera>
      <always_on>1</always_on><update_rate>20</update_rate><visualize>true</visualize>
      <topic>/camera/image_raw</topic>
    </sensor>
  </gazebo>

  <gazebo>
    <plugin filename="gz-sim-diff-drive-system" name="gz::sim::systems::DiffDrive">
      <left_joint>left_wheel_joint</left_joint>
      <right_joint>right_wheel_joint</right_joint>
      <wheel_separation>0.36</wheel_separation>
      <wheel_radius>0.1</wheel_radius>
      <topic>/cmd_vel</topic>
      <odom_topic>/model/bot_v2/odometry</odom_topic>
      <publish_odom>true</publish_odom>
    </plugin>
  </gazebo>
</robot>